{
 "cells": [
  {
   "cell_type": "code",
   "execution_count": null,
   "metadata": {},
   "outputs": [
    {
     "name": "stderr",
     "output_type": "stream",
     "text": [
      " * Running on http://127.0.0.1:8050/ (Press CTRL+C to quit)\n",
      "127.0.0.1 - - [24/Feb/2018 14:32:18] \"GET / HTTP/1.1\" 200 -\n",
      "127.0.0.1 - - [24/Feb/2018 14:32:18] \"GET /_dash-layout HTTP/1.1\" 200 -\n",
      "127.0.0.1 - - [24/Feb/2018 14:32:18] \"GET /_dash-dependencies HTTP/1.1\" 200 -\n",
      "E:\\anaconda\\envs\\vision\\lib\\site-packages\\pandas_datareader\\google\\daily.py:40: UnstableAPIWarning:\n",
      "\n",
      "\n",
      "The Google Finance API has not been stable since late 2017. Requests seem\n",
      "to fail at random. Failure is especially common when bulk downloading.\n",
      "\n",
      "\n",
      "[2018-02-24 14:32:20,367] ERROR in app: Exception on /_dash-update-component [POST]\n",
      "Traceback (most recent call last):\n",
      "  File \"E:\\anaconda\\envs\\vision\\lib\\site-packages\\flask\\app.py\", line 1982, in wsgi_app\n",
      "    response = self.full_dispatch_request()\n",
      "  File \"E:\\anaconda\\envs\\vision\\lib\\site-packages\\flask\\app.py\", line 1614, in full_dispatch_request\n",
      "    rv = self.handle_user_exception(e)\n",
      "  File \"E:\\anaconda\\envs\\vision\\lib\\site-packages\\flask\\app.py\", line 1517, in handle_user_exception\n",
      "    reraise(exc_type, exc_value, tb)\n",
      "  File \"E:\\anaconda\\envs\\vision\\lib\\site-packages\\flask\\_compat.py\", line 33, in reraise\n",
      "    raise value\n",
      "  File \"E:\\anaconda\\envs\\vision\\lib\\site-packages\\flask\\app.py\", line 1612, in full_dispatch_request\n",
      "    rv = self.dispatch_request()\n",
      "  File \"E:\\anaconda\\envs\\vision\\lib\\site-packages\\flask\\app.py\", line 1598, in dispatch_request\n",
      "    return self.view_functions[rule.endpoint](**req.view_args)\n",
      "  File \"E:\\anaconda\\envs\\vision\\lib\\site-packages\\dash\\dash.py\", line 556, in dispatch\n",
      "    return self.callback_map[target_id]['callback'](*args)\n",
      "  File \"E:\\anaconda\\envs\\vision\\lib\\site-packages\\dash\\dash.py\", line 513, in add_context\n",
      "    output_value = func(*args, **kwargs)\n",
      "  File \"<ipython-input-1-f33fd5aebd0e>\", line 25, in update_value\n",
      "    df = web.DataReader(input_data, 'google', start, end)\n",
      "  File \"E:\\anaconda\\envs\\vision\\lib\\site-packages\\pandas_datareader\\data.py\", line 315, in DataReader\n",
      "    session=session).read()\n",
      "  File \"E:\\anaconda\\envs\\vision\\lib\\site-packages\\pandas_datareader\\base.py\", line 206, in read\n",
      "    params=self._get_params(self.symbols))\n",
      "  File \"E:\\anaconda\\envs\\vision\\lib\\site-packages\\pandas_datareader\\base.py\", line 84, in _read_one_data\n",
      "    out = self._read_url_as_StringIO(url, params=params)\n",
      "  File \"E:\\anaconda\\envs\\vision\\lib\\site-packages\\pandas_datareader\\base.py\", line 95, in _read_url_as_StringIO\n",
      "    response = self._get_response(url, params=params)\n",
      "  File \"E:\\anaconda\\envs\\vision\\lib\\site-packages\\pandas_datareader\\base.py\", line 155, in _get_response\n",
      "    raise RemoteDataError(msg)\n",
      "pandas_datareader._utils.RemoteDataError: Unable to read URL: https://finance.google.com/finance/historical?q=&startdate=Jan+01%2C+2015&enddate=Feb+24%2C+2018&output=csv\n",
      "Response Text:\n",
      "b'<!DOCTYPE html><html lang=en><meta charset=utf-8><meta name=viewport content=\"initial-scale=1, minimum-scale=1, width=device-width\"><title>Error 400 (Not Found)!!1</title><style>*{margin:0;padding:0}html,code{font:15px/22px arial,sans-serif}html{background:#fff;color:#222;padding:15px}body{color:#222;text-align:unset;margin:7% auto 0;max-width:390px;min-height:180px;padding:30px 0 15px;}* > body{background:url(//www.google.com/images/errors/robot.png) 100% 5px no-repeat;padding-right:205px}p{margin:11px 0 22px;overflow:hidden}pre{white-space:pre-wrap;}ins{color:#777;text-decoration:none}a img{border:0}@media screen and (max-width:772px){body{background:none;margin-top:0;max-width:none;padding-right:0}}#logo{background:url(//www.google.com/images/branding/googlelogo/1x/googlelogo_color_150x54dp.png) no-repeat;margin-left:-5px}@media only screen and (min-resolution:192dpi){#logo{background:url(//www.google.com/images/branding/googlelogo/2x/googlelogo_color_150x54dp.png) no-repeat 0% 0%/100% 100%;-moz-border-image:url(//www.google.com/images/branding/googlelogo/2x/googlelogo_color_150x54dp.png) 0}}@media only screen and (-webkit-min-device-pixel-ratio:2){#logo{background:url(//www.google.com/images/branding/googlelogo/2x/googlelogo_color_150x54dp.png) no-repeat;-webkit-background-size:100% 100%}}#logo{display:inline-block;height:54px;width:150px}</style><div id=\"af-error-container\"><a href=//www.google.com><span id=logo aria-label=Google></span></a><p><b>400.</b> <ins>That\\xe2\\x80\\x99s an error.</ins><p>The requested URL was not found on this server. <ins>That\\xe2\\x80\\x99s all we know.</ins></div>'\n",
      "127.0.0.1 - - [24/Feb/2018 14:32:20] \"POST /_dash-update-component HTTP/1.1\" 500 -\n",
      "127.0.0.1 - - [24/Feb/2018 14:32:20] \"GET /favicon.ico HTTP/1.1\" 200 -\n",
      "127.0.0.1 - - [24/Feb/2018 14:32:24] \"POST /_dash-update-component HTTP/1.1\" 200 -\n",
      "[2018-02-24 14:32:25,605] ERROR in app: Exception on /_dash-update-component [POST]\n",
      "Traceback (most recent call last):\n",
      "  File \"E:\\anaconda\\envs\\vision\\lib\\site-packages\\flask\\app.py\", line 1982, in wsgi_app\n",
      "    response = self.full_dispatch_request()\n",
      "  File \"E:\\anaconda\\envs\\vision\\lib\\site-packages\\flask\\app.py\", line 1614, in full_dispatch_request\n",
      "    rv = self.handle_user_exception(e)\n",
      "  File \"E:\\anaconda\\envs\\vision\\lib\\site-packages\\flask\\app.py\", line 1517, in handle_user_exception\n",
      "    reraise(exc_type, exc_value, tb)\n",
      "  File \"E:\\anaconda\\envs\\vision\\lib\\site-packages\\flask\\_compat.py\", line 33, in reraise\n",
      "    raise value\n",
      "  File \"E:\\anaconda\\envs\\vision\\lib\\site-packages\\flask\\app.py\", line 1612, in full_dispatch_request\n",
      "    rv = self.dispatch_request()\n",
      "  File \"E:\\anaconda\\envs\\vision\\lib\\site-packages\\flask\\app.py\", line 1598, in dispatch_request\n",
      "    return self.view_functions[rule.endpoint](**req.view_args)\n",
      "  File \"E:\\anaconda\\envs\\vision\\lib\\site-packages\\dash\\dash.py\", line 556, in dispatch\n",
      "    return self.callback_map[target_id]['callback'](*args)\n",
      "  File \"E:\\anaconda\\envs\\vision\\lib\\site-packages\\dash\\dash.py\", line 513, in add_context\n",
      "    output_value = func(*args, **kwargs)\n",
      "  File \"<ipython-input-1-f33fd5aebd0e>\", line 25, in update_value\n",
      "    df = web.DataReader(input_data, 'google', start, end)\n",
      "  File \"E:\\anaconda\\envs\\vision\\lib\\site-packages\\pandas_datareader\\data.py\", line 315, in DataReader\n",
      "    session=session).read()\n",
      "  File \"E:\\anaconda\\envs\\vision\\lib\\site-packages\\pandas_datareader\\base.py\", line 206, in read\n",
      "    params=self._get_params(self.symbols))\n",
      "  File \"E:\\anaconda\\envs\\vision\\lib\\site-packages\\pandas_datareader\\base.py\", line 84, in _read_one_data\n",
      "    out = self._read_url_as_StringIO(url, params=params)\n",
      "  File \"E:\\anaconda\\envs\\vision\\lib\\site-packages\\pandas_datareader\\base.py\", line 95, in _read_url_as_StringIO\n",
      "    response = self._get_response(url, params=params)\n",
      "  File \"E:\\anaconda\\envs\\vision\\lib\\site-packages\\pandas_datareader\\base.py\", line 155, in _get_response\n",
      "    raise RemoteDataError(msg)\n",
      "pandas_datareader._utils.RemoteDataError: Unable to read URL: https://finance.google.com/finance/historical?q=n%C3%BC&startdate=Jan+01%2C+2015&enddate=Feb+24%2C+2018&output=csv\n",
      "Response Text:\n",
      "b'<!DOCTYPE html><html lang=en><meta charset=utf-8><meta name=viewport content=\"initial-scale=1, minimum-scale=1, width=device-width\"><title>Error 400 (Not Found)!!1</title><style>*{margin:0;padding:0}html,code{font:15px/22px arial,sans-serif}html{background:#fff;color:#222;padding:15px}body{color:#222;text-align:unset;margin:7% auto 0;max-width:390px;min-height:180px;padding:30px 0 15px;}* > body{background:url(//www.google.com/images/errors/robot.png) 100% 5px no-repeat;padding-right:205px}p{margin:11px 0 22px;overflow:hidden}pre{white-space:pre-wrap;}ins{color:#777;text-decoration:none}a img{border:0}@media screen and (max-width:772px){body{background:none;margin-top:0;max-width:none;padding-right:0}}#logo{background:url(//www.google.com/images/branding/googlelogo/1x/googlelogo_color_150x54dp.png) no-repeat;margin-left:-5px}@media only screen and (min-resolution:192dpi){#logo{background:url(//www.google.com/images/branding/googlelogo/2x/googlelogo_color_150x54dp.png) no-repeat 0% 0%/100% 100%;-moz-border-image:url(//www.google.com/images/branding/googlelogo/2x/googlelogo_color_150x54dp.png) 0}}@media only screen and (-webkit-min-device-pixel-ratio:2){#logo{background:url(//www.google.com/images/branding/googlelogo/2x/googlelogo_color_150x54dp.png) no-repeat;-webkit-background-size:100% 100%}}#logo{display:inline-block;height:54px;width:150px}</style><div id=\"af-error-container\"><a href=//www.google.com><span id=logo aria-label=Google></span></a><p><b>400.</b> <ins>That\\xe2\\x80\\x99s an error.</ins><p>The requested URL was not found on this server. <ins>That\\xe2\\x80\\x99s all we know.</ins></div>'\n",
      "127.0.0.1 - - [24/Feb/2018 14:32:25] \"POST /_dash-update-component HTTP/1.1\" 500 -\n",
      "[2018-02-24 14:32:26,870] ERROR in app: Exception on /_dash-update-component [POST]\n",
      "Traceback (most recent call last):\n",
      "  File \"E:\\anaconda\\envs\\vision\\lib\\site-packages\\flask\\app.py\", line 1982, in wsgi_app\n",
      "    response = self.full_dispatch_request()\n",
      "  File \"E:\\anaconda\\envs\\vision\\lib\\site-packages\\flask\\app.py\", line 1614, in full_dispatch_request\n",
      "    rv = self.handle_user_exception(e)\n",
      "  File \"E:\\anaconda\\envs\\vision\\lib\\site-packages\\flask\\app.py\", line 1517, in handle_user_exception\n",
      "    reraise(exc_type, exc_value, tb)\n",
      "  File \"E:\\anaconda\\envs\\vision\\lib\\site-packages\\flask\\_compat.py\", line 33, in reraise\n",
      "    raise value\n",
      "  File \"E:\\anaconda\\envs\\vision\\lib\\site-packages\\flask\\app.py\", line 1612, in full_dispatch_request\n",
      "    rv = self.dispatch_request()\n",
      "  File \"E:\\anaconda\\envs\\vision\\lib\\site-packages\\flask\\app.py\", line 1598, in dispatch_request\n",
      "    return self.view_functions[rule.endpoint](**req.view_args)\n",
      "  File \"E:\\anaconda\\envs\\vision\\lib\\site-packages\\dash\\dash.py\", line 556, in dispatch\n",
      "    return self.callback_map[target_id]['callback'](*args)\n",
      "  File \"E:\\anaconda\\envs\\vision\\lib\\site-packages\\dash\\dash.py\", line 513, in add_context\n",
      "    output_value = func(*args, **kwargs)\n",
      "  File \"<ipython-input-1-f33fd5aebd0e>\", line 25, in update_value\n",
      "    df = web.DataReader(input_data, 'google', start, end)\n",
      "  File \"E:\\anaconda\\envs\\vision\\lib\\site-packages\\pandas_datareader\\data.py\", line 315, in DataReader\n",
      "    session=session).read()\n",
      "  File \"E:\\anaconda\\envs\\vision\\lib\\site-packages\\pandas_datareader\\base.py\", line 206, in read\n",
      "    params=self._get_params(self.symbols))\n",
      "  File \"E:\\anaconda\\envs\\vision\\lib\\site-packages\\pandas_datareader\\base.py\", line 84, in _read_one_data\n",
      "    out = self._read_url_as_StringIO(url, params=params)\n",
      "  File \"E:\\anaconda\\envs\\vision\\lib\\site-packages\\pandas_datareader\\base.py\", line 95, in _read_url_as_StringIO\n",
      "    response = self._get_response(url, params=params)\n",
      "  File \"E:\\anaconda\\envs\\vision\\lib\\site-packages\\pandas_datareader\\base.py\", line 155, in _get_response\n",
      "    raise RemoteDataError(msg)\n",
      "pandas_datareader._utils.RemoteDataError: Unable to read URL: https://finance.google.com/finance/historical?q=n%C3%BC%27d&startdate=Jan+01%2C+2015&enddate=Feb+24%2C+2018&output=csv\n",
      "Response Text:\n",
      "b'<!DOCTYPE html><html lang=en><meta charset=utf-8><meta name=viewport content=\"initial-scale=1, minimum-scale=1, width=device-width\"><title>Error 400 (Not Found)!!1</title><style>*{margin:0;padding:0}html,code{font:15px/22px arial,sans-serif}html{background:#fff;color:#222;padding:15px}body{color:#222;text-align:unset;margin:7% auto 0;max-width:390px;min-height:180px;padding:30px 0 15px;}* > body{background:url(//www.google.com/images/errors/robot.png) 100% 5px no-repeat;padding-right:205px}p{margin:11px 0 22px;overflow:hidden}pre{white-space:pre-wrap;}ins{color:#777;text-decoration:none}a img{border:0}@media screen and (max-width:772px){body{background:none;margin-top:0;max-width:none;padding-right:0}}#logo{background:url(//www.google.com/images/branding/googlelogo/1x/googlelogo_color_150x54dp.png) no-repeat;margin-left:-5px}@media only screen and (min-resolution:192dpi){#logo{background:url(//www.google.com/images/branding/googlelogo/2x/googlelogo_color_150x54dp.png) no-repeat 0% 0%/100% 100%;-moz-border-image:url(//www.google.com/images/branding/googlelogo/2x/googlelogo_color_150x54dp.png) 0}}@media only screen and (-webkit-min-device-pixel-ratio:2){#logo{background:url(//www.google.com/images/branding/googlelogo/2x/googlelogo_color_150x54dp.png) no-repeat;-webkit-background-size:100% 100%}}#logo{display:inline-block;height:54px;width:150px}</style><div id=\"af-error-container\"><a href=//www.google.com><span id=logo aria-label=Google></span></a><p><b>400.</b> <ins>That\\xe2\\x80\\x99s an error.</ins><p>The requested URL was not found on this server. <ins>That\\xe2\\x80\\x99s all we know.</ins></div>'\n",
      "127.0.0.1 - - [24/Feb/2018 14:32:26] \"POST /_dash-update-component HTTP/1.1\" 500 -\n",
      "[2018-02-24 14:32:27,874] ERROR in app: Exception on /_dash-update-component [POST]\n",
      "Traceback (most recent call last):\n",
      "  File \"E:\\anaconda\\envs\\vision\\lib\\site-packages\\flask\\app.py\", line 1982, in wsgi_app\n",
      "    response = self.full_dispatch_request()\n",
      "  File \"E:\\anaconda\\envs\\vision\\lib\\site-packages\\flask\\app.py\", line 1614, in full_dispatch_request\n",
      "    rv = self.handle_user_exception(e)\n",
      "  File \"E:\\anaconda\\envs\\vision\\lib\\site-packages\\flask\\app.py\", line 1517, in handle_user_exception\n",
      "    reraise(exc_type, exc_value, tb)\n",
      "  File \"E:\\anaconda\\envs\\vision\\lib\\site-packages\\flask\\_compat.py\", line 33, in reraise\n",
      "    raise value\n",
      "  File \"E:\\anaconda\\envs\\vision\\lib\\site-packages\\flask\\app.py\", line 1612, in full_dispatch_request\n",
      "    rv = self.dispatch_request()\n",
      "  File \"E:\\anaconda\\envs\\vision\\lib\\site-packages\\flask\\app.py\", line 1598, in dispatch_request\n",
      "    return self.view_functions[rule.endpoint](**req.view_args)\n",
      "  File \"E:\\anaconda\\envs\\vision\\lib\\site-packages\\dash\\dash.py\", line 556, in dispatch\n",
      "    return self.callback_map[target_id]['callback'](*args)\n",
      "  File \"E:\\anaconda\\envs\\vision\\lib\\site-packages\\dash\\dash.py\", line 513, in add_context\n",
      "    output_value = func(*args, **kwargs)\n",
      "  File \"<ipython-input-1-f33fd5aebd0e>\", line 25, in update_value\n",
      "    df = web.DataReader(input_data, 'google', start, end)\n",
      "  File \"E:\\anaconda\\envs\\vision\\lib\\site-packages\\pandas_datareader\\data.py\", line 315, in DataReader\n",
      "    session=session).read()\n",
      "  File \"E:\\anaconda\\envs\\vision\\lib\\site-packages\\pandas_datareader\\base.py\", line 206, in read\n",
      "    params=self._get_params(self.symbols))\n",
      "  File \"E:\\anaconda\\envs\\vision\\lib\\site-packages\\pandas_datareader\\base.py\", line 84, in _read_one_data\n",
      "    out = self._read_url_as_StringIO(url, params=params)\n",
      "  File \"E:\\anaconda\\envs\\vision\\lib\\site-packages\\pandas_datareader\\base.py\", line 95, in _read_url_as_StringIO\n",
      "    response = self._get_response(url, params=params)\n",
      "  File \"E:\\anaconda\\envs\\vision\\lib\\site-packages\\pandas_datareader\\base.py\", line 155, in _get_response\n",
      "    raise RemoteDataError(msg)\n",
      "pandas_datareader._utils.RemoteDataError: Unable to read URL: https://finance.google.com/finance/historical?q=n%C3%BC%27da&startdate=Jan+01%2C+2015&enddate=Feb+24%2C+2018&output=csv\n",
      "Response Text:\n",
      "b'<!DOCTYPE html><html lang=en><meta charset=utf-8><meta name=viewport content=\"initial-scale=1, minimum-scale=1, width=device-width\"><title>Error 400 (Not Found)!!1</title><style>*{margin:0;padding:0}html,code{font:15px/22px arial,sans-serif}html{background:#fff;color:#222;padding:15px}body{color:#222;text-align:unset;margin:7% auto 0;max-width:390px;min-height:180px;padding:30px 0 15px;}* > body{background:url(//www.google.com/images/errors/robot.png) 100% 5px no-repeat;padding-right:205px}p{margin:11px 0 22px;overflow:hidden}pre{white-space:pre-wrap;}ins{color:#777;text-decoration:none}a img{border:0}@media screen and (max-width:772px){body{background:none;margin-top:0;max-width:none;padding-right:0}}#logo{background:url(//www.google.com/images/branding/googlelogo/1x/googlelogo_color_150x54dp.png) no-repeat;margin-left:-5px}@media only screen and (min-resolution:192dpi){#logo{background:url(//www.google.com/images/branding/googlelogo/2x/googlelogo_color_150x54dp.png) no-repeat 0% 0%/100% 100%;-moz-border-image:url(//www.google.com/images/branding/googlelogo/2x/googlelogo_color_150x54dp.png) 0}}@media only screen and (-webkit-min-device-pixel-ratio:2){#logo{background:url(//www.google.com/images/branding/googlelogo/2x/googlelogo_color_150x54dp.png) no-repeat;-webkit-background-size:100% 100%}}#logo{display:inline-block;height:54px;width:150px}</style><div id=\"af-error-container\"><a href=//www.google.com><span id=logo aria-label=Google></span></a><p><b>400.</b> <ins>That\\xe2\\x80\\x99s an error.</ins><p>The requested URL was not found on this server. <ins>That\\xe2\\x80\\x99s all we know.</ins></div>'\n",
      "127.0.0.1 - - [24/Feb/2018 14:32:27] \"POST /_dash-update-component HTTP/1.1\" 500 -\n",
      "127.0.0.1 - - [24/Feb/2018 14:32:28] \"POST /_dash-update-component HTTP/1.1\" 200 -\n",
      "127.0.0.1 - - [24/Feb/2018 14:32:29] \"POST /_dash-update-component HTTP/1.1\" 200 -\n"
     ]
    }
   ],
   "source": [
    "import pandas_datareader.data as web\n",
    "import datetime\n",
    "import dash\n",
    "import dash_core_components as dcc\n",
    "import dash_html_components as html\n",
    "from dash.dependencies import Input, Output\n",
    "\n",
    "app = dash.Dash()\n",
    "\n",
    "app.layout = html.Div(children=[\n",
    "    html.Div(children='''\n",
    "        键入美股代码:\n",
    "    '''),\n",
    "    dcc.Input(id='input', value='', type='text'),\n",
    "    html.Div(id='output-graph'),\n",
    "])\n",
    "\n",
    "@app.callback(\n",
    "    Output(component_id='output-graph', component_property='children'),\n",
    "    [Input(component_id='input', component_property='value')]\n",
    ")\n",
    "def update_value(input_data):\n",
    "    start = datetime.datetime(2015, 1, 1)\n",
    "    end = datetime.datetime.now()\n",
    "    df = web.DataReader(input_data, 'google', start, end)\n",
    "\n",
    "    return dcc.Graph(\n",
    "        id='example-graph',\n",
    "        figure={\n",
    "            'data': [\n",
    "                {'x': df.index, 'y': df.Close, 'type': 'line', 'name': input_data},\n",
    "            ],\n",
    "            'layout': {\n",
    "                'title': input_data\n",
    "            }\n",
    "        }\n",
    "    )\n",
    "\n",
    "if __name__ == '__main__':\n",
    "    app.run_server()"
   ]
  }
 ],
 "metadata": {
  "kernelspec": {
   "display_name": "Python 3",
   "language": "python",
   "name": "python3"
  },
  "language_info": {
   "codemirror_mode": {
    "name": "ipython",
    "version": 3
   },
   "file_extension": ".py",
   "mimetype": "text/x-python",
   "name": "python",
   "nbconvert_exporter": "python",
   "pygments_lexer": "ipython3",
   "version": "3.6.4"
  }
 },
 "nbformat": 4,
 "nbformat_minor": 2
}
